WARNING:discord.client:PyNaCl is not installed, voice will NOT be supported
ERROR:discord.app_commands.tree:Ignoring exception in command 'inventory'
Traceback (most recent call last):
  File "C:\Users\oakne\AppData\Roaming\Python\Python310\site-packages\discord\app_commands\commands.py", line 862, in _do_call
    return await self._callback(interaction, **params)  # type: ignore
  File "C:\Users\oakne\Desktop\DiscordBots\KittyKaravans\Kitties&Karavans.py", line 271, in inventory
    karavan_data = load_data('karavan_data.json')
  File "C:\Users\oakne\Desktop\DiscordBots\KittyKaravans\Kitties&Karavans.py", line 97, in load_data
    return json.load(file)
  File "C:\Users\oakne\AppData\Local\Programs\Python\Python310\lib\json\__init__.py", line 293, in load
    return loads(fp.read(),
  File "C:\Users\oakne\AppData\Local\Programs\Python\Python310\lib\json\__init__.py", line 346, in loads
    return _default_decoder.decode(s)
  File "C:\Users\oakne\AppData\Local\Programs\Python\Python310\lib\json\decoder.py", line 337, in decode
    obj, end = self.raw_decode(s, idx=_w(s, 0).end())
  File "C:\Users\oakne\AppData\Local\Programs\Python\Python310\lib\json\decoder.py", line 355, in raw_decode
    raise JSONDecodeError("Expecting value", s, err.value) from None
json.decoder.JSONDecodeError: Expecting value: line 1 column 113 (char 112)

The above exception was the direct cause of the following exception:

Traceback (most recent call last):
  File "C:\Users\oakne\AppData\Roaming\Python\Python310\site-packages\discord\app_commands\tree.py", line 1242, in _call
    await command._invoke_with_namespace(interaction, namespace)
  File "C:\Users\oakne\AppData\Roaming\Python\Python310\site-packages\discord\app_commands\commands.py", line 887, in _invoke_with_namespace
    return await self._do_call(interaction, transformed_values)
  File "C:\Users\oakne\AppData\Roaming\Python\Python310\site-packages\discord\app_commands\commands.py", line 880, in _do_call
    raise CommandInvokeError(self, e) from e
discord.app_commands.errors.CommandInvokeError: Command 'inventory' raised an exception: JSONDecodeError: Expecting value: line 1 column 113 (char 112)
ERROR:discord.client:Ignoring exception in on_interaction
Traceback (most recent call last):
  File "C:\Users\oakne\AppData\Roaming\Python\Python310\site-packages\discord\client.py", line 409, in _run_event
    await coro(*args, **kwargs)
  File "C:\Users\oakne\Desktop\DiscordBots\KittyKaravans\Kitties&Karavans.py", line 84, in on_interaction
    await bot.tree.dispatch_interaction(interaction)
AttributeError: 'CommandTree' object has no attribute 'dispatch_interaction'
WARNING:discord.client:PyNaCl is not installed, voice will NOT be supported
ERROR:discord.app_commands.tree:Ignoring exception in command 'inventory'
Traceback (most recent call last):
  File "C:\Users\oakne\AppData\Roaming\Python\Python310\site-packages\discord\app_commands\commands.py", line 862, in _do_call
    return await self._callback(interaction, **params)  # type: ignore
  File "C:\Users\oakne\Desktop\DiscordBots\KittyKaravans\Kitties&Karavans.py", line 268, in inventory
    karavan_data = load_data('karavan_data.json')
  File "C:\Users\oakne\Desktop\DiscordBots\KittyKaravans\Kitties&Karavans.py", line 97, in load_data
    return json.load(file)
  File "C:\Users\oakne\AppData\Local\Programs\Python\Python310\lib\json\__init__.py", line 293, in load
    return loads(fp.read(),
  File "C:\Users\oakne\AppData\Local\Programs\Python\Python310\lib\json\__init__.py", line 346, in loads
    return _default_decoder.decode(s)
  File "C:\Users\oakne\AppData\Local\Programs\Python\Python310\lib\json\decoder.py", line 337, in decode
    obj, end = self.raw_decode(s, idx=_w(s, 0).end())
  File "C:\Users\oakne\AppData\Local\Programs\Python\Python310\lib\json\decoder.py", line 355, in raw_decode
    raise JSONDecodeError("Expecting value", s, err.value) from None
json.decoder.JSONDecodeError: Expecting value: line 1 column 113 (char 112)

The above exception was the direct cause of the following exception:

Traceback (most recent call last):
  File "C:\Users\oakne\AppData\Roaming\Python\Python310\site-packages\discord\app_commands\tree.py", line 1242, in _call
    await command._invoke_with_namespace(interaction, namespace)
  File "C:\Users\oakne\AppData\Roaming\Python\Python310\site-packages\discord\app_commands\commands.py", line 887, in _invoke_with_namespace
    return await self._do_call(interaction, transformed_values)
  File "C:\Users\oakne\AppData\Roaming\Python\Python310\site-packages\discord\app_commands\commands.py", line 880, in _do_call
    raise CommandInvokeError(self, e) from e
discord.app_commands.errors.CommandInvokeError: Command 'inventory' raised an exception: JSONDecodeError: Expecting value: line 1 column 113 (char 112)
ERROR:discord.client:Ignoring exception in on_interaction
Traceback (most recent call last):
  File "C:\Users\oakne\AppData\Roaming\Python\Python310\site-packages\discord\client.py", line 409, in _run_event
    await coro(*args, **kwargs)
  File "C:\Users\oakne\Desktop\DiscordBots\KittyKaravans\Kitties&Karavans.py", line 84, in on_interaction
    await bot.tree.dispatch_interaction(interaction)
AttributeError: 'CommandTree' object has no attribute 'dispatch_interaction'
WARNING:discord.client:PyNaCl is not installed, voice will NOT be supported
ERROR:discord.app_commands.tree:Ignoring exception in command 'inventory'
Traceback (most recent call last):
  File "C:\Users\oakne\AppData\Roaming\Python\Python310\site-packages\discord\app_commands\commands.py", line 862, in _do_call
    return await self._callback(interaction, **params)  # type: ignore
  File "C:\Users\oakne\Desktop\DiscordBots\KittyKaravans\Kitties&Karavans.py", line 268, in inventory
    karavan_data = load_data('karavan_data.json')
  File "C:\Users\oakne\Desktop\DiscordBots\KittyKaravans\Kitties&Karavans.py", line 97, in load_data
    return json.load(file)
  File "C:\Users\oakne\AppData\Local\Programs\Python\Python310\lib\json\__init__.py", line 293, in load
    return loads(fp.read(),
  File "C:\Users\oakne\AppData\Local\Programs\Python\Python310\lib\json\__init__.py", line 346, in loads
    return _default_decoder.decode(s)
  File "C:\Users\oakne\AppData\Local\Programs\Python\Python310\lib\json\decoder.py", line 337, in decode
    obj, end = self.raw_decode(s, idx=_w(s, 0).end())
  File "C:\Users\oakne\AppData\Local\Programs\Python\Python310\lib\json\decoder.py", line 355, in raw_decode
    raise JSONDecodeError("Expecting value", s, err.value) from None
json.decoder.JSONDecodeError: Expecting value: line 1 column 113 (char 112)

The above exception was the direct cause of the following exception:

Traceback (most recent call last):
  File "C:\Users\oakne\AppData\Roaming\Python\Python310\site-packages\discord\app_commands\tree.py", line 1242, in _call
    await command._invoke_with_namespace(interaction, namespace)
  File "C:\Users\oakne\AppData\Roaming\Python\Python310\site-packages\discord\app_commands\commands.py", line 887, in _invoke_with_namespace
    return await self._do_call(interaction, transformed_values)
  File "C:\Users\oakne\AppData\Roaming\Python\Python310\site-packages\discord\app_commands\commands.py", line 880, in _do_call
    raise CommandInvokeError(self, e) from e
discord.app_commands.errors.CommandInvokeError: Command 'inventory' raised an exception: JSONDecodeError: Expecting value: line 1 column 113 (char 112)
ERROR:discord.client:Ignoring exception in on_interaction
Traceback (most recent call last):
  File "C:\Users\oakne\AppData\Roaming\Python\Python310\site-packages\discord\client.py", line 409, in _run_event
    await coro(*args, **kwargs)
  File "C:\Users\oakne\Desktop\DiscordBots\KittyKaravans\Kitties&Karavans.py", line 84, in on_interaction
    await bot.tree.dispatch_interaction(interaction)
AttributeError: 'CommandTree' object has no attribute 'dispatch_interaction'
WARNING:discord.client:PyNaCl is not installed, voice will NOT be supported
ERROR:discord.app_commands.tree:Ignoring exception in command 'inventory'
Traceback (most recent call last):
  File "C:\Users\oakne\AppData\Roaming\Python\Python310\site-packages\discord\app_commands\commands.py", line 862, in _do_call
    return await self._callback(interaction, **params)  # type: ignore
  File "C:\Users\oakne\Desktop\DiscordBots\KittyKaravans\Kitties&Karavans.py", line 268, in inventory
    karavan_data = load_data('karavan_data.json')
  File "C:\Users\oakne\Desktop\DiscordBots\KittyKaravans\Kitties&Karavans.py", line 97, in load_data
    return json.load(file)
  File "C:\Users\oakne\AppData\Local\Programs\Python\Python310\lib\json\__init__.py", line 293, in load
    return loads(fp.read(),
  File "C:\Users\oakne\AppData\Local\Programs\Python\Python310\lib\json\__init__.py", line 346, in loads
    return _default_decoder.decode(s)
  File "C:\Users\oakne\AppData\Local\Programs\Python\Python310\lib\json\decoder.py", line 337, in decode
    obj, end = self.raw_decode(s, idx=_w(s, 0).end())
  File "C:\Users\oakne\AppData\Local\Programs\Python\Python310\lib\json\decoder.py", line 355, in raw_decode
    raise JSONDecodeError("Expecting value", s, err.value) from None
json.decoder.JSONDecodeError: Expecting value: line 1 column 113 (char 112)

The above exception was the direct cause of the following exception:

Traceback (most recent call last):
  File "C:\Users\oakne\AppData\Roaming\Python\Python310\site-packages\discord\app_commands\tree.py", line 1242, in _call
    await command._invoke_with_namespace(interaction, namespace)
  File "C:\Users\oakne\AppData\Roaming\Python\Python310\site-packages\discord\app_commands\commands.py", line 887, in _invoke_with_namespace
    return await self._do_call(interaction, transformed_values)
  File "C:\Users\oakne\AppData\Roaming\Python\Python310\site-packages\discord\app_commands\commands.py", line 880, in _do_call
    raise CommandInvokeError(self, e) from e
discord.app_commands.errors.CommandInvokeError: Command 'inventory' raised an exception: JSONDecodeError: Expecting value: line 1 column 113 (char 112)
ERROR:discord.client:Ignoring exception in on_interaction
Traceback (most recent call last):
  File "C:\Users\oakne\AppData\Roaming\Python\Python310\site-packages\discord\client.py", line 409, in _run_event
    await coro(*args, **kwargs)
  File "C:\Users\oakne\Desktop\DiscordBots\KittyKaravans\Kitties&Karavans.py", line 84, in on_interaction
    await bot.tree.dispatch_interaction(interaction)
AttributeError: 'CommandTree' object has no attribute 'dispatch_interaction'
ERROR:discord.client:Ignoring exception in on_interaction
Traceback (most recent call last):
  File "C:\Users\oakne\AppData\Roaming\Python\Python310\site-packages\discord\client.py", line 409, in _run_event
    await coro(*args, **kwargs)
  File "C:\Users\oakne\Desktop\DiscordBots\KittyKaravans\Kitties&Karavans.py", line 84, in on_interaction
    await bot.tree.dispatch_interaction(interaction)
AttributeError: 'CommandTree' object has no attribute 'dispatch_interaction'
ERROR:discord.app_commands.tree:Ignoring exception in command 'kick'
Traceback (most recent call last):
  File "C:\Users\oakne\Desktop\DiscordBots\KittyKaravans\Kitties&Karavans.py", line 219, in kick
    karavan_data = load_data('karavan_data.json')
  File "C:\Users\oakne\Desktop\DiscordBots\KittyKaravans\Kitties&Karavans.py", line 97, in load_data
    return json.load(file)
  File "C:\Users\oakne\AppData\Local\Programs\Python\Python310\lib\json\__init__.py", line 293, in load
    return loads(fp.read(),
  File "C:\Users\oakne\AppData\Local\Programs\Python\Python310\lib\json\__init__.py", line 346, in loads
    return _default_decoder.decode(s)
  File "C:\Users\oakne\AppData\Local\Programs\Python\Python310\lib\json\decoder.py", line 337, in decode
    obj, end = self.raw_decode(s, idx=_w(s, 0).end())
  File "C:\Users\oakne\AppData\Local\Programs\Python\Python310\lib\json\decoder.py", line 355, in raw_decode
    raise JSONDecodeError("Expecting value", s, err.value) from None
json.decoder.JSONDecodeError: Expecting value: line 1 column 113 (char 112)

During handling of the above exception, another exception occurred:

Traceback (most recent call last):
  File "C:\Users\oakne\AppData\Roaming\Python\Python310\site-packages\discord\app_commands\commands.py", line 862, in _do_call
    return await self._callback(interaction, **params)  # type: ignore
  File "C:\Users\oakne\Desktop\DiscordBots\KittyKaravans\Kitties&Karavans.py", line 231, in kick
    await interaction.response.send_message("Error kicking user.")
  File "C:\Users\oakne\AppData\Roaming\Python\Python310\site-packages\discord\interactions.py", line 743, in send_message
    raise InteractionResponded(self._parent)
discord.errors.InteractionResponded: This interaction has already been responded to before

The above exception was the direct cause of the following exception:

Traceback (most recent call last):
  File "C:\Users\oakne\AppData\Roaming\Python\Python310\site-packages\discord\app_commands\tree.py", line 1242, in _call
    await command._invoke_with_namespace(interaction, namespace)
  File "C:\Users\oakne\AppData\Roaming\Python\Python310\site-packages\discord\app_commands\commands.py", line 887, in _invoke_with_namespace
    return await self._do_call(interaction, transformed_values)
  File "C:\Users\oakne\AppData\Roaming\Python\Python310\site-packages\discord\app_commands\commands.py", line 880, in _do_call
    raise CommandInvokeError(self, e) from e
discord.app_commands.errors.CommandInvokeError: Command 'kick' raised an exception: InteractionResponded: This interaction has already been responded to before
WARNING:discord.client:PyNaCl is not installed, voice will NOT be supported
ERROR:discord.client:Ignoring exception in on_interaction
Traceback (most recent call last):
  File "C:\Users\oakne\AppData\Roaming\Python\Python310\site-packages\discord\client.py", line 409, in _run_event
    await coro(*args, **kwargs)
  File "C:\Users\oakne\Desktop\DiscordBots\KittyKaravans\Kitties&Karavans.py", line 84, in on_interaction
    await bot.tree.dispatch_interaction(interaction)
AttributeError: 'CommandTree' object has no attribute 'dispatch_interaction'
WARNING:discord.client:PyNaCl is not installed, voice will NOT be supported
ERROR:discord.app_commands.tree:Ignoring exception in command 'inventory'
Traceback (most recent call last):
  File "C:\Users\oakne\AppData\Roaming\Python\Python310\site-packages\discord\app_commands\commands.py", line 862, in _do_call
    return await self._callback(interaction, **params)  # type: ignore
  File "C:\Users\oakne\Desktop\DiscordBots\KittyKaravans\Kitties&Karavans.py", line 257, in inventory
    karavan_data = load_data('karavan_data.json')
  File "C:\Users\oakne\Desktop\DiscordBots\KittyKaravans\Kitties&Karavans.py", line 97, in load_data
    return json.load(file)
  File "C:\Users\oakne\AppData\Local\Programs\Python\Python310\lib\json\__init__.py", line 293, in load
    return loads(fp.read(),
  File "C:\Users\oakne\AppData\Local\Programs\Python\Python310\lib\json\__init__.py", line 346, in loads
    return _default_decoder.decode(s)
  File "C:\Users\oakne\AppData\Local\Programs\Python\Python310\lib\json\decoder.py", line 337, in decode
    obj, end = self.raw_decode(s, idx=_w(s, 0).end())
  File "C:\Users\oakne\AppData\Local\Programs\Python\Python310\lib\json\decoder.py", line 355, in raw_decode
    raise JSONDecodeError("Expecting value", s, err.value) from None
json.decoder.JSONDecodeError: Expecting value: line 1 column 113 (char 112)

The above exception was the direct cause of the following exception:

Traceback (most recent call last):
  File "C:\Users\oakne\AppData\Roaming\Python\Python310\site-packages\discord\app_commands\tree.py", line 1242, in _call
    await command._invoke_with_namespace(interaction, namespace)
  File "C:\Users\oakne\AppData\Roaming\Python\Python310\site-packages\discord\app_commands\commands.py", line 887, in _invoke_with_namespace
    return await self._do_call(interaction, transformed_values)
  File "C:\Users\oakne\AppData\Roaming\Python\Python310\site-packages\discord\app_commands\commands.py", line 880, in _do_call
    raise CommandInvokeError(self, e) from e
discord.app_commands.errors.CommandInvokeError: Command 'inventory' raised an exception: JSONDecodeError: Expecting value: line 1 column 113 (char 112)
ERROR:discord.client:Ignoring exception in on_interaction
Traceback (most recent call last):
  File "C:\Users\oakne\AppData\Roaming\Python\Python310\site-packages\discord\client.py", line 409, in _run_event
    await coro(*args, **kwargs)
  File "C:\Users\oakne\Desktop\DiscordBots\KittyKaravans\Kitties&Karavans.py", line 84, in on_interaction
    await bot.tree.dispatch_interaction(interaction)
AttributeError: 'CommandTree' object has no attribute 'dispatch_interaction'
ERROR:discord.client:Ignoring exception in on_interaction
Traceback (most recent call last):
  File "C:\Users\oakne\AppData\Roaming\Python\Python310\site-packages\discord\client.py", line 409, in _run_event
    await coro(*args, **kwargs)
  File "C:\Users\oakne\Desktop\DiscordBots\KittyKaravans\Kitties&Karavans.py", line 84, in on_interaction
    await bot.tree.dispatch_interaction(interaction)
AttributeError: 'CommandTree' object has no attribute 'dispatch_interaction'
ERROR:discord.client:Ignoring exception in on_interaction
Traceback (most recent call last):
  File "C:\Users\oakne\AppData\Roaming\Python\Python310\site-packages\discord\client.py", line 409, in _run_event
    await coro(*args, **kwargs)
  File "C:\Users\oakne\Desktop\DiscordBots\KittyKaravans\Kitties&Karavans.py", line 84, in on_interaction
    await bot.tree.dispatch_interaction(interaction)
AttributeError: 'CommandTree' object has no attribute 'dispatch_interaction'
WARNING:discord.client:PyNaCl is not installed, voice will NOT be supported
ERROR:discord.client:Ignoring exception in on_interaction
Traceback (most recent call last):
  File "C:\Users\oakne\AppData\Roaming\Python\Python310\site-packages\discord\client.py", line 409, in _run_event
    await coro(*args, **kwargs)
  File "C:\Users\oakne\Desktop\DiscordBots\KittyKaravans\Kitties&Karavans.py", line 84, in on_interaction
    await bot.tree.dispatch_interaction(interaction)
AttributeError: 'CommandTree' object has no attribute 'dispatch_interaction'
ERROR:discord.app_commands.tree:Ignoring exception in command 'inventory'
Traceback (most recent call last):
  File "C:\Users\oakne\AppData\Roaming\Python\Python310\site-packages\discord\app_commands\commands.py", line 862, in _do_call
    return await self._callback(interaction, **params)  # type: ignore
  File "C:\Users\oakne\Desktop\DiscordBots\KittyKaravans\Kitties&Karavans.py", line 276, in inventory
    await interaction.response.send_message(user_message_counts)
  File "C:\Users\oakne\AppData\Roaming\Python\Python310\site-packages\discord\interactions.py", line 743, in send_message
    raise InteractionResponded(self._parent)
discord.errors.InteractionResponded: This interaction has already been responded to before

The above exception was the direct cause of the following exception:

Traceback (most recent call last):
  File "C:\Users\oakne\AppData\Roaming\Python\Python310\site-packages\discord\app_commands\tree.py", line 1242, in _call
    await command._invoke_with_namespace(interaction, namespace)
  File "C:\Users\oakne\AppData\Roaming\Python\Python310\site-packages\discord\app_commands\commands.py", line 887, in _invoke_with_namespace
    return await self._do_call(interaction, transformed_values)
  File "C:\Users\oakne\AppData\Roaming\Python\Python310\site-packages\discord\app_commands\commands.py", line 880, in _do_call
    raise CommandInvokeError(self, e) from e
discord.app_commands.errors.CommandInvokeError: Command 'inventory' raised an exception: InteractionResponded: This interaction has already been responded to before
WARNING:discord.client:PyNaCl is not installed, voice will NOT be supported
ERROR:discord.client:Ignoring exception in on_interaction
Traceback (most recent call last):
  File "C:\Users\oakne\AppData\Roaming\Python\Python310\site-packages\discord\client.py", line 409, in _run_event
    await coro(*args, **kwargs)
  File "C:\Users\oakne\Desktop\DiscordBots\KittyKaravans\Kitties&Karavans.py", line 84, in on_interaction
    await bot.tree.dispatch_interaction(interaction)
AttributeError: 'CommandTree' object has no attribute 'dispatch_interaction'
ERROR:discord.client:Ignoring exception in on_interaction
Traceback (most recent call last):
  File "C:\Users\oakne\AppData\Roaming\Python\Python310\site-packages\discord\client.py", line 409, in _run_event
    await coro(*args, **kwargs)
  File "C:\Users\oakne\Desktop\DiscordBots\KittyKaravans\Kitties&Karavans.py", line 84, in on_interaction
    await bot.tree.dispatch_interaction(interaction)
AttributeError: 'CommandTree' object has no attribute 'dispatch_interaction'
ERROR:discord.client:Ignoring exception in on_interaction
Traceback (most recent call last):
  File "C:\Users\oakne\AppData\Roaming\Python\Python310\site-packages\discord\client.py", line 409, in _run_event
    await coro(*args, **kwargs)
  File "C:\Users\oakne\Desktop\DiscordBots\KittyKaravans\Kitties&Karavans.py", line 84, in on_interaction
    await bot.tree.dispatch_interaction(interaction)
AttributeError: 'CommandTree' object has no attribute 'dispatch_interaction'
WARNING:discord.client:PyNaCl is not installed, voice will NOT be supported
ERROR:discord.client:Ignoring exception in on_interaction
Traceback (most recent call last):
  File "C:\Users\oakne\AppData\Roaming\Python\Python310\site-packages\discord\client.py", line 409, in _run_event
    await coro(*args, **kwargs)
  File "C:\Users\oakne\Desktop\DiscordBots\KittyKaravans\Kitties&Karavans.py", line 84, in on_interaction
    await bot.tree.dispatch_interaction(interaction)
AttributeError: 'CommandTree' object has no attribute 'dispatch_interaction'
WARNING:discord.client:PyNaCl is not installed, voice will NOT be supported
ERROR:discord.client:Ignoring exception in on_interaction
Traceback (most recent call last):
  File "C:\Users\oakne\AppData\Roaming\Python\Python310\site-packages\discord\client.py", line 409, in _run_event
    await coro(*args, **kwargs)
  File "C:\Users\oakne\Desktop\DiscordBots\KittyKaravans\Kitties&Karavans.py", line 84, in on_interaction
    await bot.tree.dispatch_interaction(interaction)
AttributeError: 'CommandTree' object has no attribute 'dispatch_interaction'
WARNING:discord.client:PyNaCl is not installed, voice will NOT be supported
ERROR:discord.app_commands.tree:Ignoring exception in command 'inventory'
Traceback (most recent call last):
  File "C:\Users\oakne\AppData\Roaming\Python\Python310\site-packages\discord\app_commands\commands.py", line 862, in _do_call
    return await self._callback(interaction, **params)  # type: ignore
  File "C:\Users\oakne\Desktop\DiscordBots\KittyKaravans\Kitties&Karavans.py", line 271, in inventory
    embed.add_field(name='\U0001fad3', value=user_message_counts[member]['\U0001fad3'])
KeyError: <Member id=290848742905610241 name='thrallhouse' discriminator='0' bot=False nick='Vibe Scrying Plane Raider' guild=<Guild id=605154816330825758 name='Lorebos' shard_id=0 chunked=True member_count=19>>

The above exception was the direct cause of the following exception:

Traceback (most recent call last):
  File "C:\Users\oakne\AppData\Roaming\Python\Python310\site-packages\discord\app_commands\tree.py", line 1242, in _call
    await command._invoke_with_namespace(interaction, namespace)
  File "C:\Users\oakne\AppData\Roaming\Python\Python310\site-packages\discord\app_commands\commands.py", line 887, in _invoke_with_namespace
    return await self._do_call(interaction, transformed_values)
  File "C:\Users\oakne\AppData\Roaming\Python\Python310\site-packages\discord\app_commands\commands.py", line 880, in _do_call
    raise CommandInvokeError(self, e) from e
discord.app_commands.errors.CommandInvokeError: Command 'inventory' raised an exception: KeyError: <Member id=290848742905610241 name='thrallhouse' discriminator='0' bot=False nick='Vibe Scrying Plane Raider' guild=<Guild id=605154816330825758 name='Lorebos' shard_id=0 chunked=True member_count=19>>
ERROR:discord.client:Ignoring exception in on_interaction
Traceback (most recent call last):
  File "C:\Users\oakne\AppData\Roaming\Python\Python310\site-packages\discord\client.py", line 409, in _run_event
    await coro(*args, **kwargs)
  File "C:\Users\oakne\Desktop\DiscordBots\KittyKaravans\Kitties&Karavans.py", line 84, in on_interaction
    await bot.tree.dispatch_interaction(interaction)
AttributeError: 'CommandTree' object has no attribute 'dispatch_interaction'
WARNING:discord.client:PyNaCl is not installed, voice will NOT be supported
ERROR:discord.client:Ignoring exception in on_interaction
Traceback (most recent call last):
  File "C:\Users\oakne\AppData\Roaming\Python\Python310\site-packages\discord\client.py", line 409, in _run_event
    await coro(*args, **kwargs)
  File "C:\Users\oakne\Desktop\DiscordBots\KittyKaravans\Kitties&Karavans.py", line 84, in on_interaction
    await bot.tree.dispatch_interaction(interaction)
AttributeError: 'CommandTree' object has no attribute 'dispatch_interaction'
WARNING:discord.client:PyNaCl is not installed, voice will NOT be supported
ERROR:discord.app_commands.tree:Ignoring exception in command 'inventory'
Traceback (most recent call last):
  File "C:\Users\oakne\AppData\Roaming\Python\Python310\site-packages\discord\app_commands\commands.py", line 862, in _do_call
    return await self._callback(interaction, **params)  # type: ignore
  File "C:\Users\oakne\Desktop\DiscordBots\KittyKaravans\Kitties&Karavans.py", line 271, in inventory
    embed.add_field(name='test', value=user_message_counts[member]['test'])
KeyError: <Member id=290848742905610241 name='thrallhouse' discriminator='0' bot=False nick='Vibe Scrying Plane Raider' guild=<Guild id=605154816330825758 name='Lorebos' shard_id=0 chunked=True member_count=19>>

The above exception was the direct cause of the following exception:

Traceback (most recent call last):
  File "C:\Users\oakne\AppData\Roaming\Python\Python310\site-packages\discord\app_commands\tree.py", line 1242, in _call
    await command._invoke_with_namespace(interaction, namespace)
  File "C:\Users\oakne\AppData\Roaming\Python\Python310\site-packages\discord\app_commands\commands.py", line 887, in _invoke_with_namespace
    return await self._do_call(interaction, transformed_values)
  File "C:\Users\oakne\AppData\Roaming\Python\Python310\site-packages\discord\app_commands\commands.py", line 880, in _do_call
    raise CommandInvokeError(self, e) from e
discord.app_commands.errors.CommandInvokeError: Command 'inventory' raised an exception: KeyError: <Member id=290848742905610241 name='thrallhouse' discriminator='0' bot=False nick='Vibe Scrying Plane Raider' guild=<Guild id=605154816330825758 name='Lorebos' shard_id=0 chunked=True member_count=19>>
ERROR:discord.client:Ignoring exception in on_interaction
Traceback (most recent call last):
  File "C:\Users\oakne\AppData\Roaming\Python\Python310\site-packages\discord\client.py", line 409, in _run_event
    await coro(*args, **kwargs)
  File "C:\Users\oakne\Desktop\DiscordBots\KittyKaravans\Kitties&Karavans.py", line 84, in on_interaction
    await bot.tree.dispatch_interaction(interaction)
AttributeError: 'CommandTree' object has no attribute 'dispatch_interaction'
WARNING:discord.client:PyNaCl is not installed, voice will NOT be supported
ERROR:discord.app_commands.tree:Ignoring exception in command 'inventory'
Traceback (most recent call last):
  File "C:\Users\oakne\AppData\Roaming\Python\Python310\site-packages\discord\app_commands\commands.py", line 862, in _do_call
    return await self._callback(interaction, **params)  # type: ignore
  File "C:\Users\oakne\Desktop\DiscordBots\KittyKaravans\Kitties&Karavans.py", line 272, in inventory
    embed.add_field(name='\U0001f35e', value=user_message_counts[member]['\U0001f35e'])
KeyError: <Member id=290848742905610241 name='thrallhouse' discriminator='0' bot=False nick='Vibe Scrying Plane Raider' guild=<Guild id=605154816330825758 name='Lorebos' shard_id=0 chunked=True member_count=19>>

The above exception was the direct cause of the following exception:

Traceback (most recent call last):
  File "C:\Users\oakne\AppData\Roaming\Python\Python310\site-packages\discord\app_commands\tree.py", line 1242, in _call
    await command._invoke_with_namespace(interaction, namespace)
  File "C:\Users\oakne\AppData\Roaming\Python\Python310\site-packages\discord\app_commands\commands.py", line 887, in _invoke_with_namespace
    return await self._do_call(interaction, transformed_values)
  File "C:\Users\oakne\AppData\Roaming\Python\Python310\site-packages\discord\app_commands\commands.py", line 880, in _do_call
    raise CommandInvokeError(self, e) from e
discord.app_commands.errors.CommandInvokeError: Command 'inventory' raised an exception: KeyError: <Member id=290848742905610241 name='thrallhouse' discriminator='0' bot=False nick='Vibe Scrying Plane Raider' guild=<Guild id=605154816330825758 name='Lorebos' shard_id=0 chunked=True member_count=19>>
ERROR:discord.client:Ignoring exception in on_interaction
Traceback (most recent call last):
  File "C:\Users\oakne\AppData\Roaming\Python\Python310\site-packages\discord\client.py", line 409, in _run_event
    await coro(*args, **kwargs)
  File "C:\Users\oakne\Desktop\DiscordBots\KittyKaravans\Kitties&Karavans.py", line 84, in on_interaction
    await bot.tree.dispatch_interaction(interaction)
AttributeError: 'CommandTree' object has no attribute 'dispatch_interaction'
WARNING:discord.client:PyNaCl is not installed, voice will NOT be supported
ERROR:discord.app_commands.tree:Ignoring exception in command 'inventory'
Traceback (most recent call last):
  File "C:\Users\oakne\AppData\Roaming\Python\Python310\site-packages\discord\app_commands\commands.py", line 862, in _do_call
    return await self._callback(interaction, **params)  # type: ignore
  File "C:\Users\oakne\Desktop\DiscordBots\KittyKaravans\Kitties&Karavans.py", line 259, in inventory
    print(user_message_counts[member]['\U0001fad3'])
UnboundLocalError: local variable 'member' referenced before assignment

The above exception was the direct cause of the following exception:

Traceback (most recent call last):
  File "C:\Users\oakne\AppData\Roaming\Python\Python310\site-packages\discord\app_commands\tree.py", line 1242, in _call
    await command._invoke_with_namespace(interaction, namespace)
  File "C:\Users\oakne\AppData\Roaming\Python\Python310\site-packages\discord\app_commands\commands.py", line 887, in _invoke_with_namespace
    return await self._do_call(interaction, transformed_values)
  File "C:\Users\oakne\AppData\Roaming\Python\Python310\site-packages\discord\app_commands\commands.py", line 880, in _do_call
    raise CommandInvokeError(self, e) from e
discord.app_commands.errors.CommandInvokeError: Command 'inventory' raised an exception: UnboundLocalError: local variable 'member' referenced before assignment
ERROR:discord.client:Ignoring exception in on_interaction
Traceback (most recent call last):
  File "C:\Users\oakne\AppData\Roaming\Python\Python310\site-packages\discord\client.py", line 409, in _run_event
    await coro(*args, **kwargs)
  File "C:\Users\oakne\Desktop\DiscordBots\KittyKaravans\Kitties&Karavans.py", line 84, in on_interaction
    await bot.tree.dispatch_interaction(interaction)
AttributeError: 'CommandTree' object has no attribute 'dispatch_interaction'
WARNING:discord.client:PyNaCl is not installed, voice will NOT be supported
ERROR:discord.app_commands.tree:Ignoring exception in command 'inventory'
Traceback (most recent call last):
  File "C:\Users\oakne\AppData\Roaming\Python\Python310\site-packages\discord\app_commands\commands.py", line 862, in _do_call
    return await self._callback(interaction, **params)  # type: ignore
  File "C:\Users\oakne\Desktop\DiscordBots\KittyKaravans\Kitties&Karavans.py", line 263, in inventory
    print(user_message_counts[member]['\U0001fad3'])
UnboundLocalError: local variable 'member' referenced before assignment

The above exception was the direct cause of the following exception:

Traceback (most recent call last):
  File "C:\Users\oakne\AppData\Roaming\Python\Python310\site-packages\discord\app_commands\tree.py", line 1242, in _call
    await command._invoke_with_namespace(interaction, namespace)
  File "C:\Users\oakne\AppData\Roaming\Python\Python310\site-packages\discord\app_commands\commands.py", line 887, in _invoke_with_namespace
    return await self._do_call(interaction, transformed_values)
  File "C:\Users\oakne\AppData\Roaming\Python\Python310\site-packages\discord\app_commands\commands.py", line 880, in _do_call
    raise CommandInvokeError(self, e) from e
discord.app_commands.errors.CommandInvokeError: Command 'inventory' raised an exception: UnboundLocalError: local variable 'member' referenced before assignment
ERROR:discord.client:Ignoring exception in on_interaction
Traceback (most recent call last):
  File "C:\Users\oakne\AppData\Roaming\Python\Python310\site-packages\discord\client.py", line 409, in _run_event
    await coro(*args, **kwargs)
  File "C:\Users\oakne\Desktop\DiscordBots\KittyKaravans\Kitties&Karavans.py", line 84, in on_interaction
    await bot.tree.dispatch_interaction(interaction)
AttributeError: 'CommandTree' object has no attribute 'dispatch_interaction'
WARNING:discord.client:PyNaCl is not installed, voice will NOT be supported
ERROR:discord.app_commands.tree:Ignoring exception in command 'inventory'
Traceback (most recent call last):
  File "C:\Users\oakne\AppData\Roaming\Python\Python310\site-packages\discord\app_commands\commands.py", line 862, in _do_call
    return await self._callback(interaction, **params)  # type: ignore
  File "C:\Users\oakne\Desktop\DiscordBots\KittyKaravans\Kitties&Karavans.py", line 259, in inventory
    print(member)
UnboundLocalError: local variable 'member' referenced before assignment

The above exception was the direct cause of the following exception:

Traceback (most recent call last):
  File "C:\Users\oakne\AppData\Roaming\Python\Python310\site-packages\discord\app_commands\tree.py", line 1242, in _call
    await command._invoke_with_namespace(interaction, namespace)
  File "C:\Users\oakne\AppData\Roaming\Python\Python310\site-packages\discord\app_commands\commands.py", line 887, in _invoke_with_namespace
    return await self._do_call(interaction, transformed_values)
  File "C:\Users\oakne\AppData\Roaming\Python\Python310\site-packages\discord\app_commands\commands.py", line 880, in _do_call
    raise CommandInvokeError(self, e) from e
discord.app_commands.errors.CommandInvokeError: Command 'inventory' raised an exception: UnboundLocalError: local variable 'member' referenced before assignment
ERROR:discord.client:Ignoring exception in on_interaction
Traceback (most recent call last):
  File "C:\Users\oakne\AppData\Roaming\Python\Python310\site-packages\discord\client.py", line 409, in _run_event
    await coro(*args, **kwargs)
  File "C:\Users\oakne\Desktop\DiscordBots\KittyKaravans\Kitties&Karavans.py", line 84, in on_interaction
    await bot.tree.dispatch_interaction(interaction)
AttributeError: 'CommandTree' object has no attribute 'dispatch_interaction'
WARNING:discord.client:PyNaCl is not installed, voice will NOT be supported
ERROR:discord.client:Ignoring exception in on_interaction
Traceback (most recent call last):
  File "C:\Users\oakne\AppData\Roaming\Python\Python310\site-packages\discord\client.py", line 409, in _run_event
    await coro(*args, **kwargs)
  File "C:\Users\oakne\Desktop\DiscordBots\KittyKaravans\Kitties&Karavans.py", line 84, in on_interaction
    await bot.tree.dispatch_interaction(interaction)
AttributeError: 'CommandTree' object has no attribute 'dispatch_interaction'
WARNING:discord.client:PyNaCl is not installed, voice will NOT be supported
ERROR:discord.app_commands.tree:Ignoring exception in command 'inventory'
Traceback (most recent call last):
  File "C:\Users\oakne\AppData\Roaming\Python\Python310\site-packages\discord\app_commands\commands.py", line 862, in _do_call
    return await self._callback(interaction, **params)  # type: ignore
  File "C:\Users\oakne\Desktop\DiscordBots\KittyKaravans\Kitties&Karavans.py", line 270, in inventory
    print(user_message_counts[member]['\U0001fad3'])
KeyError: <Member id=290848742905610241 name='thrallhouse' discriminator='0' bot=False nick='Vibe Scrying Plane Raider' guild=<Guild id=605154816330825758 name='Lorebos' shard_id=0 chunked=True member_count=19>>

The above exception was the direct cause of the following exception:

Traceback (most recent call last):
  File "C:\Users\oakne\AppData\Roaming\Python\Python310\site-packages\discord\app_commands\tree.py", line 1242, in _call
    await command._invoke_with_namespace(interaction, namespace)
  File "C:\Users\oakne\AppData\Roaming\Python\Python310\site-packages\discord\app_commands\commands.py", line 887, in _invoke_with_namespace
    return await self._do_call(interaction, transformed_values)
  File "C:\Users\oakne\AppData\Roaming\Python\Python310\site-packages\discord\app_commands\commands.py", line 880, in _do_call
    raise CommandInvokeError(self, e) from e
discord.app_commands.errors.CommandInvokeError: Command 'inventory' raised an exception: KeyError: <Member id=290848742905610241 name='thrallhouse' discriminator='0' bot=False nick='Vibe Scrying Plane Raider' guild=<Guild id=605154816330825758 name='Lorebos' shard_id=0 chunked=True member_count=19>>
ERROR:discord.client:Ignoring exception in on_interaction
Traceback (most recent call last):
  File "C:\Users\oakne\AppData\Roaming\Python\Python310\site-packages\discord\client.py", line 409, in _run_event
    await coro(*args, **kwargs)
  File "C:\Users\oakne\Desktop\DiscordBots\KittyKaravans\Kitties&Karavans.py", line 84, in on_interaction
    await bot.tree.dispatch_interaction(interaction)
AttributeError: 'CommandTree' object has no attribute 'dispatch_interaction'
WARNING:discord.client:PyNaCl is not installed, voice will NOT be supported
ERROR:discord.app_commands.tree:Ignoring exception in command 'inventory'
Traceback (most recent call last):
  File "C:\Users\oakne\AppData\Roaming\Python\Python310\site-packages\discord\app_commands\commands.py", line 862, in _do_call
    return await self._callback(interaction, **params)  # type: ignore
  File "C:\Users\oakne\Desktop\DiscordBots\KittyKaravans\Kitties&Karavans.py", line 270, in inventory
    print(user_message_counts[member]['\ud83e\uded3'])
KeyError: <Member id=290848742905610241 name='thrallhouse' discriminator='0' bot=False nick='Vibe Scrying Plane Raider' guild=<Guild id=605154816330825758 name='Lorebos' shard_id=0 chunked=True member_count=19>>

The above exception was the direct cause of the following exception:

Traceback (most recent call last):
  File "C:\Users\oakne\AppData\Roaming\Python\Python310\site-packages\discord\app_commands\tree.py", line 1242, in _call
    await command._invoke_with_namespace(interaction, namespace)
  File "C:\Users\oakne\AppData\Roaming\Python\Python310\site-packages\discord\app_commands\commands.py", line 887, in _invoke_with_namespace
    return await self._do_call(interaction, transformed_values)
  File "C:\Users\oakne\AppData\Roaming\Python\Python310\site-packages\discord\app_commands\commands.py", line 880, in _do_call
    raise CommandInvokeError(self, e) from e
discord.app_commands.errors.CommandInvokeError: Command 'inventory' raised an exception: KeyError: <Member id=290848742905610241 name='thrallhouse' discriminator='0' bot=False nick='Vibe Scrying Plane Raider' guild=<Guild id=605154816330825758 name='Lorebos' shard_id=0 chunked=True member_count=19>>
ERROR:discord.client:Ignoring exception in on_interaction
Traceback (most recent call last):
  File "C:\Users\oakne\AppData\Roaming\Python\Python310\site-packages\discord\client.py", line 409, in _run_event
    await coro(*args, **kwargs)
  File "C:\Users\oakne\Desktop\DiscordBots\KittyKaravans\Kitties&Karavans.py", line 84, in on_interaction
    await bot.tree.dispatch_interaction(interaction)
AttributeError: 'CommandTree' object has no attribute 'dispatch_interaction'
WARNING:discord.client:PyNaCl is not installed, voice will NOT be supported
ERROR:discord.app_commands.tree:Ignoring exception in command 'inventory'
Traceback (most recent call last):
  File "C:\Users\oakne\AppData\Roaming\Python\Python310\site-packages\discord\app_commands\commands.py", line 862, in _do_call
    return await self._callback(interaction, **params)  # type: ignore
  File "C:\Users\oakne\Desktop\DiscordBots\KittyKaravans\Kitties&Karavans.py", line 270, in inventory
    print(user_message_counts[member])
KeyError: <Member id=290848742905610241 name='thrallhouse' discriminator='0' bot=False nick='Vibe Scrying Plane Raider' guild=<Guild id=605154816330825758 name='Lorebos' shard_id=0 chunked=True member_count=19>>

The above exception was the direct cause of the following exception:

Traceback (most recent call last):
  File "C:\Users\oakne\AppData\Roaming\Python\Python310\site-packages\discord\app_commands\tree.py", line 1242, in _call
    await command._invoke_with_namespace(interaction, namespace)
  File "C:\Users\oakne\AppData\Roaming\Python\Python310\site-packages\discord\app_commands\commands.py", line 887, in _invoke_with_namespace
    return await self._do_call(interaction, transformed_values)
  File "C:\Users\oakne\AppData\Roaming\Python\Python310\site-packages\discord\app_commands\commands.py", line 880, in _do_call
    raise CommandInvokeError(self, e) from e
discord.app_commands.errors.CommandInvokeError: Command 'inventory' raised an exception: KeyError: <Member id=290848742905610241 name='thrallhouse' discriminator='0' bot=False nick='Vibe Scrying Plane Raider' guild=<Guild id=605154816330825758 name='Lorebos' shard_id=0 chunked=True member_count=19>>
ERROR:discord.client:Ignoring exception in on_interaction
Traceback (most recent call last):
  File "C:\Users\oakne\AppData\Roaming\Python\Python310\site-packages\discord\client.py", line 409, in _run_event
    await coro(*args, **kwargs)
  File "C:\Users\oakne\Desktop\DiscordBots\KittyKaravans\Kitties&Karavans.py", line 84, in on_interaction
    await bot.tree.dispatch_interaction(interaction)
AttributeError: 'CommandTree' object has no attribute 'dispatch_interaction'
WARNING:discord.client:PyNaCl is not installed, voice will NOT be supported
ERROR:discord.app_commands.tree:Ignoring exception in command 'inventory'
Traceback (most recent call last):
  File "C:\Users\oakne\AppData\Roaming\Python\Python310\site-packages\discord\app_commands\commands.py", line 862, in _do_call
    return await self._callback(interaction, **params)  # type: ignore
  File "C:\Users\oakne\Desktop\DiscordBots\KittyKaravans\Kitties&Karavans.py", line 270, in inventory
    print(user_message_counts[member]['\U0001fad3'])
KeyError: <Member id=290848742905610241 name='thrallhouse' discriminator='0' bot=False nick='Vibe Scrying Plane Raider' guild=<Guild id=605154816330825758 name='Lorebos' shard_id=0 chunked=True member_count=19>>

The above exception was the direct cause of the following exception:

Traceback (most recent call last):
  File "C:\Users\oakne\AppData\Roaming\Python\Python310\site-packages\discord\app_commands\tree.py", line 1242, in _call
    await command._invoke_with_namespace(interaction, namespace)
  File "C:\Users\oakne\AppData\Roaming\Python\Python310\site-packages\discord\app_commands\commands.py", line 887, in _invoke_with_namespace
    return await self._do_call(interaction, transformed_values)
  File "C:\Users\oakne\AppData\Roaming\Python\Python310\site-packages\discord\app_commands\commands.py", line 880, in _do_call
    raise CommandInvokeError(self, e) from e
discord.app_commands.errors.CommandInvokeError: Command 'inventory' raised an exception: KeyError: <Member id=290848742905610241 name='thrallhouse' discriminator='0' bot=False nick='Vibe Scrying Plane Raider' guild=<Guild id=605154816330825758 name='Lorebos' shard_id=0 chunked=True member_count=19>>
ERROR:discord.client:Ignoring exception in on_interaction
Traceback (most recent call last):
  File "C:\Users\oakne\AppData\Roaming\Python\Python310\site-packages\discord\client.py", line 409, in _run_event
    await coro(*args, **kwargs)
  File "C:\Users\oakne\Desktop\DiscordBots\KittyKaravans\Kitties&Karavans.py", line 84, in on_interaction
    await bot.tree.dispatch_interaction(interaction)
AttributeError: 'CommandTree' object has no attribute 'dispatch_interaction'
ERROR:discord.client:Ignoring exception in on_interaction
Traceback (most recent call last):
  File "C:\Users\oakne\AppData\Roaming\Python\Python310\site-packages\discord\client.py", line 409, in _run_event
    await coro(*args, **kwargs)
  File "C:\Users\oakne\Desktop\DiscordBots\KittyKaravans\Kitties&Karavans.py", line 84, in on_interaction
    await bot.tree.dispatch_interaction(interaction)
AttributeError: 'CommandTree' object has no attribute 'dispatch_interaction'
ERROR:discord.app_commands.tree:Ignoring exception in command 'inventory'
Traceback (most recent call last):
  File "C:\Users\oakne\AppData\Roaming\Python\Python310\site-packages\discord\app_commands\commands.py", line 862, in _do_call
    return await self._callback(interaction, **params)  # type: ignore
  File "C:\Users\oakne\Desktop\DiscordBots\KittyKaravans\Kitties&Karavans.py", line 270, in inventory
    print(user_message_counts[member]['\U0001fad3'])
KeyError: <Member id=437310224601448468 name='twisted.oak' discriminator='0' bot=False nick='Cyber Scion Dreamweaver' guild=<Guild id=605154816330825758 name='Lorebos' shard_id=0 chunked=True member_count=19>>

The above exception was the direct cause of the following exception:

Traceback (most recent call last):
  File "C:\Users\oakne\AppData\Roaming\Python\Python310\site-packages\discord\app_commands\tree.py", line 1242, in _call
    await command._invoke_with_namespace(interaction, namespace)
  File "C:\Users\oakne\AppData\Roaming\Python\Python310\site-packages\discord\app_commands\commands.py", line 887, in _invoke_with_namespace
    return await self._do_call(interaction, transformed_values)
  File "C:\Users\oakne\AppData\Roaming\Python\Python310\site-packages\discord\app_commands\commands.py", line 880, in _do_call
    raise CommandInvokeError(self, e) from e
discord.app_commands.errors.CommandInvokeError: Command 'inventory' raised an exception: KeyError: <Member id=437310224601448468 name='twisted.oak' discriminator='0' bot=False nick='Cyber Scion Dreamweaver' guild=<Guild id=605154816330825758 name='Lorebos' shard_id=0 chunked=True member_count=19>>
ERROR:discord.client:Ignoring exception in on_interaction
Traceback (most recent call last):
  File "C:\Users\oakne\AppData\Roaming\Python\Python310\site-packages\discord\client.py", line 409, in _run_event
    await coro(*args, **kwargs)
  File "C:\Users\oakne\Desktop\DiscordBots\KittyKaravans\Kitties&Karavans.py", line 84, in on_interaction
    await bot.tree.dispatch_interaction(interaction)
AttributeError: 'CommandTree' object has no attribute 'dispatch_interaction'
WARNING:discord.client:PyNaCl is not installed, voice will NOT be supported
ERROR:discord.client:Ignoring exception in on_interaction
Traceback (most recent call last):
  File "C:\Users\oakne\AppData\Roaming\Python\Python310\site-packages\discord\client.py", line 409, in _run_event
    await coro(*args, **kwargs)
  File "C:\Users\oakne\Desktop\DiscordBots\KittyKaravans\Kitties&Karavans.py", line 84, in on_interaction
    await bot.tree.dispatch_interaction(interaction)
AttributeError: 'CommandTree' object has no attribute 'dispatch_interaction'
WARNING:discord.client:PyNaCl is not installed, voice will NOT be supported
ERROR:discord.client:Ignoring exception in on_interaction
Traceback (most recent call last):
  File "C:\Users\oakne\AppData\Roaming\Python\Python310\site-packages\discord\client.py", line 409, in _run_event
    await coro(*args, **kwargs)
  File "C:\Users\oakne\Desktop\DiscordBots\KittyKaravans\Kitties&Karavans.py", line 84, in on_interaction
    await bot.tree.dispatch_interaction(interaction)
AttributeError: 'CommandTree' object has no attribute 'dispatch_interaction'
WARNING:discord.client:PyNaCl is not installed, voice will NOT be supported
ERROR:discord.client:Ignoring exception in on_interaction
Traceback (most recent call last):
  File "C:\Users\oakne\AppData\Roaming\Python\Python310\site-packages\discord\client.py", line 409, in _run_event
    await coro(*args, **kwargs)
  File "C:\Users\oakne\Desktop\DiscordBots\KittyKaravans\Kitties&Karavans.py", line 84, in on_interaction
    await bot.tree.dispatch_interaction(interaction)
AttributeError: 'CommandTree' object has no attribute 'dispatch_interaction'
WARNING:discord.client:PyNaCl is not installed, voice will NOT be supported
ERROR:discord.client:Ignoring exception in on_interaction
Traceback (most recent call last):
  File "C:\Users\oakne\AppData\Roaming\Python\Python310\site-packages\discord\client.py", line 409, in _run_event
    await coro(*args, **kwargs)
  File "C:\Users\oakne\Desktop\DiscordBots\KittyKaravans\Kitties&Karavans.py", line 84, in on_interaction
    await bot.tree.dispatch_interaction(interaction)
AttributeError: 'CommandTree' object has no attribute 'dispatch_interaction'
WARNING:discord.client:PyNaCl is not installed, voice will NOT be supported
ERROR:discord.client:Ignoring exception in on_interaction
Traceback (most recent call last):
  File "C:\Users\oakne\AppData\Roaming\Python\Python310\site-packages\discord\client.py", line 409, in _run_event
    await coro(*args, **kwargs)
  File "C:\Users\oakne\Desktop\DiscordBots\KittyKaravans\Kitties&Karavans.py", line 84, in on_interaction
    await bot.tree.dispatch_interaction(interaction)
AttributeError: 'CommandTree' object has no attribute 'dispatch_interaction'
ERROR:discord.client:Ignoring exception in on_interaction
Traceback (most recent call last):
  File "C:\Users\oakne\AppData\Roaming\Python\Python310\site-packages\discord\client.py", line 409, in _run_event
    await coro(*args, **kwargs)
  File "C:\Users\oakne\Desktop\DiscordBots\KittyKaravans\Kitties&Karavans.py", line 84, in on_interaction
    await bot.tree.dispatch_interaction(interaction)
AttributeError: 'CommandTree' object has no attribute 'dispatch_interaction'
ERROR:discord.app_commands.tree:Ignoring exception in command 'inventory'
Traceback (most recent call last):
  File "C:\Users\oakne\AppData\Roaming\Python\Python310\site-packages\discord\app_commands\commands.py", line 862, in _do_call
    return await self._callback(interaction, **params)  # type: ignore
  File "C:\Users\oakne\Desktop\DiscordBots\KittyKaravans\Kitties&Karavans.py", line 275, in inventory
    value = user_message_counts[member.name][emoji]
KeyError: 'thrallhouse'

The above exception was the direct cause of the following exception:

Traceback (most recent call last):
  File "C:\Users\oakne\AppData\Roaming\Python\Python310\site-packages\discord\app_commands\tree.py", line 1242, in _call
    await command._invoke_with_namespace(interaction, namespace)
  File "C:\Users\oakne\AppData\Roaming\Python\Python310\site-packages\discord\app_commands\commands.py", line 887, in _invoke_with_namespace
    return await self._do_call(interaction, transformed_values)
  File "C:\Users\oakne\AppData\Roaming\Python\Python310\site-packages\discord\app_commands\commands.py", line 880, in _do_call
    raise CommandInvokeError(self, e) from e
discord.app_commands.errors.CommandInvokeError: Command 'inventory' raised an exception: KeyError: 'thrallhouse'
ERROR:discord.client:Ignoring exception in on_interaction
Traceback (most recent call last):
  File "C:\Users\oakne\AppData\Roaming\Python\Python310\site-packages\discord\client.py", line 409, in _run_event
    await coro(*args, **kwargs)
  File "C:\Users\oakne\Desktop\DiscordBots\KittyKaravans\Kitties&Karavans.py", line 84, in on_interaction
    await bot.tree.dispatch_interaction(interaction)
AttributeError: 'CommandTree' object has no attribute 'dispatch_interaction'
WARNING:discord.client:PyNaCl is not installed, voice will NOT be supported
ERROR:discord.app_commands.tree:Ignoring exception in command 'inventory'
Traceback (most recent call last):
  File "C:\Users\oakne\AppData\Roaming\Python\Python310\site-packages\discord\app_commands\commands.py", line 862, in _do_call
    return await self._callback(interaction, **params)  # type: ignore
  File "C:\Users\oakne\Desktop\DiscordBots\KittyKaravans\Kitties&Karavans.py", line 275, in inventory
    value = user_message_counts[member.name][emoji]
KeyError: 'thrallhouse'

The above exception was the direct cause of the following exception:

Traceback (most recent call last):
  File "C:\Users\oakne\AppData\Roaming\Python\Python310\site-packages\discord\app_commands\tree.py", line 1242, in _call
    await command._invoke_with_namespace(interaction, namespace)
  File "C:\Users\oakne\AppData\Roaming\Python\Python310\site-packages\discord\app_commands\commands.py", line 887, in _invoke_with_namespace
    return await self._do_call(interaction, transformed_values)
  File "C:\Users\oakne\AppData\Roaming\Python\Python310\site-packages\discord\app_commands\commands.py", line 880, in _do_call
    raise CommandInvokeError(self, e) from e
discord.app_commands.errors.CommandInvokeError: Command 'inventory' raised an exception: KeyError: 'thrallhouse'
ERROR:discord.client:Ignoring exception in on_interaction
Traceback (most recent call last):
  File "C:\Users\oakne\AppData\Roaming\Python\Python310\site-packages\discord\client.py", line 409, in _run_event
    await coro(*args, **kwargs)
  File "C:\Users\oakne\Desktop\DiscordBots\KittyKaravans\Kitties&Karavans.py", line 84, in on_interaction
    await bot.tree.dispatch_interaction(interaction)
AttributeError: 'CommandTree' object has no attribute 'dispatch_interaction'
WARNING:discord.client:PyNaCl is not installed, voice will NOT be supported
ERROR:discord.app_commands.tree:Ignoring exception in command 'inventory'
Traceback (most recent call last):
  File "C:\Users\oakne\AppData\Roaming\Python\Python310\site-packages\discord\app_commands\commands.py", line 862, in _do_call
    return await self._callback(interaction, **params)  # type: ignore
  File "C:\Users\oakne\Desktop\DiscordBots\KittyKaravans\Kitties&Karavans.py", line 275, in inventory
    value = user_message_counts[member.name][emoji]
KeyError: 'etherealskull'

The above exception was the direct cause of the following exception:

Traceback (most recent call last):
  File "C:\Users\oakne\AppData\Roaming\Python\Python310\site-packages\discord\app_commands\tree.py", line 1242, in _call
    await command._invoke_with_namespace(interaction, namespace)
  File "C:\Users\oakne\AppData\Roaming\Python\Python310\site-packages\discord\app_commands\commands.py", line 887, in _invoke_with_namespace
    return await self._do_call(interaction, transformed_values)
  File "C:\Users\oakne\AppData\Roaming\Python\Python310\site-packages\discord\app_commands\commands.py", line 880, in _do_call
    raise CommandInvokeError(self, e) from e
discord.app_commands.errors.CommandInvokeError: Command 'inventory' raised an exception: KeyError: 'etherealskull'
ERROR:discord.client:Ignoring exception in on_interaction
Traceback (most recent call last):
  File "C:\Users\oakne\AppData\Roaming\Python\Python310\site-packages\discord\client.py", line 409, in _run_event
    await coro(*args, **kwargs)
  File "C:\Users\oakne\Desktop\DiscordBots\KittyKaravans\Kitties&Karavans.py", line 84, in on_interaction
    await bot.tree.dispatch_interaction(interaction)
AttributeError: 'CommandTree' object has no attribute 'dispatch_interaction'
WARNING:discord.client:PyNaCl is not installed, voice will NOT be supported
ERROR:discord.client:Ignoring exception in on_interaction
Traceback (most recent call last):
  File "C:\Users\oakne\AppData\Roaming\Python\Python310\site-packages\discord\client.py", line 409, in _run_event
    await coro(*args, **kwargs)
  File "C:\Users\oakne\Desktop\DiscordBots\KittyKaravans\Kitties&Karavans.py", line 84, in on_interaction
    await bot.tree.dispatch_interaction(interaction)
AttributeError: 'CommandTree' object has no attribute 'dispatch_interaction'
ERROR:discord.client:Ignoring exception in on_interaction
Traceback (most recent call last):
  File "C:\Users\oakne\AppData\Roaming\Python\Python310\site-packages\discord\client.py", line 409, in _run_event
    await coro(*args, **kwargs)
  File "C:\Users\oakne\Desktop\DiscordBots\KittyKaravans\Kitties&Karavans.py", line 84, in on_interaction
    await bot.tree.dispatch_interaction(interaction)
AttributeError: 'CommandTree' object has no attribute 'dispatch_interaction'
WARNING:discord.client:PyNaCl is not installed, voice will NOT be supported
ERROR:discord.client:Ignoring exception in on_interaction
Traceback (most recent call last):
  File "C:\Users\oakne\AppData\Roaming\Python\Python310\site-packages\discord\client.py", line 409, in _run_event
    await coro(*args, **kwargs)
  File "C:\Users\oakne\Desktop\DiscordBots\KittyKaravans\Kitties&Karavans.py", line 84, in on_interaction
    await bot.tree.dispatch_interaction(interaction)
AttributeError: 'CommandTree' object has no attribute 'dispatch_interaction'
WARNING:discord.client:PyNaCl is not installed, voice will NOT be supported
ERROR:discord.client:Ignoring exception in on_interaction
Traceback (most recent call last):
  File "C:\Users\oakne\AppData\Roaming\Python\Python310\site-packages\discord\client.py", line 409, in _run_event
    await coro(*args, **kwargs)
  File "C:\Users\oakne\Desktop\DiscordBots\KittyKaravans\Kitties&Karavans.py", line 84, in on_interaction
    await bot.tree.dispatch_interaction(interaction)
AttributeError: 'CommandTree' object has no attribute 'dispatch_interaction'
WARNING:discord.client:PyNaCl is not installed, voice will NOT be supported
ERROR:discord.client:Ignoring exception in on_interaction
Traceback (most recent call last):
  File "C:\Users\oakne\AppData\Roaming\Python\Python310\site-packages\discord\client.py", line 409, in _run_event
    await coro(*args, **kwargs)
  File "C:\Users\oakne\Desktop\DiscordBots\KittyKaravans\Kitties&Karavans.py", line 84, in on_interaction
    await bot.tree.dispatch_interaction(interaction)
AttributeError: 'CommandTree' object has no attribute 'dispatch_interaction'
ERROR:discord.client:Ignoring exception in on_interaction
Traceback (most recent call last):
  File "C:\Users\oakne\AppData\Roaming\Python\Python310\site-packages\discord\client.py", line 409, in _run_event
    await coro(*args, **kwargs)
  File "C:\Users\oakne\Desktop\DiscordBots\KittyKaravans\Kitties&Karavans.py", line 84, in on_interaction
    await bot.tree.dispatch_interaction(interaction)
AttributeError: 'CommandTree' object has no attribute 'dispatch_interaction'
ERROR:discord.client:Ignoring exception in on_interaction
Traceback (most recent call last):
  File "C:\Users\oakne\AppData\Roaming\Python\Python310\site-packages\discord\client.py", line 409, in _run_event
    await coro(*args, **kwargs)
  File "C:\Users\oakne\Desktop\DiscordBots\KittyKaravans\Kitties&Karavans.py", line 84, in on_interaction
    await bot.tree.dispatch_interaction(interaction)
AttributeError: 'CommandTree' object has no attribute 'dispatch_interaction'
WARNING:discord.client:PyNaCl is not installed, voice will NOT be supported
ERROR:discord.client:Ignoring exception in on_message
Traceback (most recent call last):
  File "C:\Users\oakne\AppData\Roaming\Python\Python310\site-packages\discord\client.py", line 409, in _run_event
    await coro(*args, **kwargs)
  File "C:\Users\oakne\Desktop\DiscordBots\KittyKaravans\Kitties&Karavans.py", line 124, in on_message
    user_message_counts[role_str][message.author.name] = {'\U0001fad3': 0, '\U0001f35e': 0, '\U0001f950': 0, '\U0001f96f': 0, '\U0001f95f': 0, '\U0001f36a': 0, '\U0001f369': 0, '\U0001f9c1': 0, '\U0001f370': 0}
KeyError: 'Test Karavan'
ERROR:discord.client:Ignoring exception in on_message
Traceback (most recent call last):
  File "C:\Users\oakne\AppData\Roaming\Python\Python310\site-packages\discord\client.py", line 409, in _run_event
    await coro(*args, **kwargs)
  File "C:\Users\oakne\Desktop\DiscordBots\KittyKaravans\Kitties&Karavans.py", line 124, in on_message
    user_message_counts[role_str][message.author.name] = {'\U0001fad3': 0, '\U0001f35e': 0, '\U0001f950': 0, '\U0001f96f': 0, '\U0001f95f': 0, '\U0001f36a': 0, '\U0001f369': 0, '\U0001f9c1': 0, '\U0001f370': 0}
KeyError: 'Test Karavan'
ERROR:discord.client:Ignoring exception in on_message
Traceback (most recent call last):
  File "C:\Users\oakne\AppData\Roaming\Python\Python310\site-packages\discord\client.py", line 409, in _run_event
    await coro(*args, **kwargs)
  File "C:\Users\oakne\Desktop\DiscordBots\KittyKaravans\Kitties&Karavans.py", line 124, in on_message
    user_message_counts[role_str][message.author.name] = {'\U0001fad3': 0, '\U0001f35e': 0, '\U0001f950': 0, '\U0001f96f': 0, '\U0001f95f': 0, '\U0001f36a': 0, '\U0001f369': 0, '\U0001f9c1': 0, '\U0001f370': 0}
KeyError: 'Test Karavan'
ERROR:discord.client:Ignoring exception in on_message
Traceback (most recent call last):
  File "C:\Users\oakne\AppData\Roaming\Python\Python310\site-packages\discord\client.py", line 409, in _run_event
    await coro(*args, **kwargs)
  File "C:\Users\oakne\Desktop\DiscordBots\KittyKaravans\Kitties&Karavans.py", line 124, in on_message
    user_message_counts[role_str][message.author.name] = {'\U0001fad3': 0, '\U0001f35e': 0, '\U0001f950': 0, '\U0001f96f': 0, '\U0001f95f': 0, '\U0001f36a': 0, '\U0001f369': 0, '\U0001f9c1': 0, '\U0001f370': 0}
KeyError: 'Test Karavan'
WARNING:discord.client:PyNaCl is not installed, voice will NOT be supported
ERROR:discord.client:Ignoring exception in on_message
Traceback (most recent call last):
  File "C:\Users\oakne\AppData\Roaming\Python\Python310\site-packages\discord\client.py", line 409, in _run_event
    await coro(*args, **kwargs)
  File "C:\Users\oakne\Desktop\DiscordBots\KittyKaravans\Kitties&Karavans.py", line 124, in on_message
    user_message_counts[role_str][message.author.name] = {'\U0001fad3': 0, '\U0001f35e': 0, '\U0001f950': 0, '\U0001f96f': 0, '\U0001f95f': 0, '\U0001f36a': 0, '\U0001f369': 0, '\U0001f9c1': 0, '\U0001f370': 0}
KeyError: 'Test Karavan'
ERROR:discord.client:Ignoring exception in on_message
Traceback (most recent call last):
  File "C:\Users\oakne\AppData\Roaming\Python\Python310\site-packages\discord\client.py", line 409, in _run_event
    await coro(*args, **kwargs)
  File "C:\Users\oakne\Desktop\DiscordBots\KittyKaravans\Kitties&Karavans.py", line 124, in on_message
    user_message_counts[role_str][message.author.name] = {'\U0001fad3': 0, '\U0001f35e': 0, '\U0001f950': 0, '\U0001f96f': 0, '\U0001f95f': 0, '\U0001f36a': 0, '\U0001f369': 0, '\U0001f9c1': 0, '\U0001f370': 0}
KeyError: 'Test Karavan'
ERROR:discord.client:Ignoring exception in on_message
Traceback (most recent call last):
  File "C:\Users\oakne\AppData\Roaming\Python\Python310\site-packages\discord\client.py", line 409, in _run_event
    await coro(*args, **kwargs)
  File "C:\Users\oakne\Desktop\DiscordBots\KittyKaravans\Kitties&Karavans.py", line 124, in on_message
    user_message_counts[role_str][message.author.name] = {'\U0001fad3': 0, '\U0001f35e': 0, '\U0001f950': 0, '\U0001f96f': 0, '\U0001f95f': 0, '\U0001f36a': 0, '\U0001f369': 0, '\U0001f9c1': 0, '\U0001f370': 0}
KeyError: 'Test Karavan'
ERROR:discord.client:Ignoring exception in on_message
Traceback (most recent call last):
  File "C:\Users\oakne\AppData\Roaming\Python\Python310\site-packages\discord\client.py", line 409, in _run_event
    await coro(*args, **kwargs)
  File "C:\Users\oakne\Desktop\DiscordBots\KittyKaravans\Kitties&Karavans.py", line 124, in on_message
    user_message_counts[role_str][message.author.name] = {'\U0001fad3': 0, '\U0001f35e': 0, '\U0001f950': 0, '\U0001f96f': 0, '\U0001f95f': 0, '\U0001f36a': 0, '\U0001f369': 0, '\U0001f9c1': 0, '\U0001f370': 0}
KeyError: 'Test Karavan'
ERROR:discord.client:Ignoring exception in on_message
Traceback (most recent call last):
  File "C:\Users\oakne\AppData\Roaming\Python\Python310\site-packages\discord\client.py", line 409, in _run_event
    await coro(*args, **kwargs)
  File "C:\Users\oakne\Desktop\DiscordBots\KittyKaravans\Kitties&Karavans.py", line 124, in on_message
    user_message_counts[role_str][message.author.name] = {'\U0001fad3': 0, '\U0001f35e': 0, '\U0001f950': 0, '\U0001f96f': 0, '\U0001f95f': 0, '\U0001f36a': 0, '\U0001f369': 0, '\U0001f9c1': 0, '\U0001f370': 0}
KeyError: 'Test Karavan'
ERROR:discord.client:Ignoring exception in on_message
Traceback (most recent call last):
  File "C:\Users\oakne\AppData\Roaming\Python\Python310\site-packages\discord\client.py", line 409, in _run_event
    await coro(*args, **kwargs)
  File "C:\Users\oakne\Desktop\DiscordBots\KittyKaravans\Kitties&Karavans.py", line 124, in on_message
    user_message_counts[role_str][message.author.name] = {'\U0001fad3': 0, '\U0001f35e': 0, '\U0001f950': 0, '\U0001f96f': 0, '\U0001f95f': 0, '\U0001f36a': 0, '\U0001f369': 0, '\U0001f9c1': 0, '\U0001f370': 0}
KeyError: 'Test Karavan'
ERROR:discord.client:Ignoring exception in on_message
Traceback (most recent call last):
  File "C:\Users\oakne\AppData\Roaming\Python\Python310\site-packages\discord\client.py", line 409, in _run_event
    await coro(*args, **kwargs)
  File "C:\Users\oakne\Desktop\DiscordBots\KittyKaravans\Kitties&Karavans.py", line 124, in on_message
    user_message_counts[role_str][message.author.name] = {'\U0001fad3': 0, '\U0001f35e': 0, '\U0001f950': 0, '\U0001f96f': 0, '\U0001f95f': 0, '\U0001f36a': 0, '\U0001f369': 0, '\U0001f9c1': 0, '\U0001f370': 0}
KeyError: 'Test Karavan'
WARNING:discord.client:PyNaCl is not installed, voice will NOT be supported
ERROR:discord.client:Ignoring exception in on_message
Traceback (most recent call last):
  File "C:\Users\oakne\AppData\Roaming\Python\Python310\site-packages\discord\client.py", line 409, in _run_event
    await coro(*args, **kwargs)
  File "C:\Users\oakne\Desktop\DiscordBots\KittyKaravans\Kitties&Karavans.py", line 124, in on_message
    user_message_counts[role_str][message.author.name] = {'\U0001fad3': 0, '\U0001f35e': 0, '\U0001f950': 0, '\U0001f96f': 0, '\U0001f95f': 0, '\U0001f36a': 0, '\U0001f369': 0, '\U0001f9c1': 0, '\U0001f370': 0}
KeyError: 'Test Karavan'
WARNING:discord.client:PyNaCl is not installed, voice will NOT be supported
ERROR:discord.client:Ignoring exception in on_message
Traceback (most recent call last):
  File "C:\Users\oakne\AppData\Roaming\Python\Python310\site-packages\discord\client.py", line 409, in _run_event
    await coro(*args, **kwargs)
  File "C:\Users\oakne\Desktop\DiscordBots\KittyKaravans\Kitties&Karavans.py", line 125, in on_message
    user_message_counts[role_str][message.author.name] = {'\U0001fad3': 0, '\U0001f35e': 0, '\U0001f950': 0, '\U0001f96f': 0, '\U0001f95f': 0, '\U0001f36a': 0, '\U0001f369': 0, '\U0001f9c1': 0, '\U0001f370': 0}
KeyError: 'Test Karavan'
ERROR:discord.client:Ignoring exception in on_message
Traceback (most recent call last):
  File "C:\Users\oakne\AppData\Roaming\Python\Python310\site-packages\discord\client.py", line 409, in _run_event
    await coro(*args, **kwargs)
  File "C:\Users\oakne\Desktop\DiscordBots\KittyKaravans\Kitties&Karavans.py", line 125, in on_message
    user_message_counts[role_str][message.author.name] = {'\U0001fad3': 0, '\U0001f35e': 0, '\U0001f950': 0, '\U0001f96f': 0, '\U0001f95f': 0, '\U0001f36a': 0, '\U0001f369': 0, '\U0001f9c1': 0, '\U0001f370': 0}
KeyError: 'Test Karavan'
WARNING:discord.client:PyNaCl is not installed, voice will NOT be supported
ERROR:discord.client:Ignoring exception in on_message
Traceback (most recent call last):
  File "C:\Users\oakne\AppData\Roaming\Python\Python310\site-packages\discord\client.py", line 409, in _run_event
    await coro(*args, **kwargs)
  File "C:\Users\oakne\Desktop\DiscordBots\KittyKaravans\Kitties&Karavans.py", line 118, in on_message
    user_message_counts[user.name] = {'\U0001fad3': 0, '\U0001f35e': 0, '\U0001f950': 0,'\U0001f96f': 0, '\U0001f95f': 0, '\U0001f36a': 0, '\U0001f369': 0, '\U0001f9c1': 0, '\U0001f370': 0}
NameError: name 'user' is not defined
WARNING:discord.client:PyNaCl is not installed, voice will NOT be supported
ERROR:discord.app_commands.tree:Ignoring exception in command 'inventory'
Traceback (most recent call last):
  File "C:\Users\oakne\AppData\Roaming\Python\Python310\site-packages\discord\app_commands\commands.py", line 862, in _do_call
    return await self._callback(interaction, **params)  # type: ignore
  File "C:\Users\oakne\Desktop\DiscordBots\KittyKaravans\Kitties&Karavans.py", line 275, in inventory
    value = user_message_counts[member.name][emoji]
KeyError: 'thrallhouse'

The above exception was the direct cause of the following exception:

Traceback (most recent call last):
  File "C:\Users\oakne\AppData\Roaming\Python\Python310\site-packages\discord\app_commands\tree.py", line 1242, in _call
    await command._invoke_with_namespace(interaction, namespace)
  File "C:\Users\oakne\AppData\Roaming\Python\Python310\site-packages\discord\app_commands\commands.py", line 887, in _invoke_with_namespace
    return await self._do_call(interaction, transformed_values)
  File "C:\Users\oakne\AppData\Roaming\Python\Python310\site-packages\discord\app_commands\commands.py", line 880, in _do_call
    raise CommandInvokeError(self, e) from e
discord.app_commands.errors.CommandInvokeError: Command 'inventory' raised an exception: KeyError: 'thrallhouse'
ERROR:discord.client:Ignoring exception in on_interaction
Traceback (most recent call last):
  File "C:\Users\oakne\AppData\Roaming\Python\Python310\site-packages\discord\client.py", line 409, in _run_event
    await coro(*args, **kwargs)
  File "C:\Users\oakne\Desktop\DiscordBots\KittyKaravans\Kitties&Karavans.py", line 84, in on_interaction
    await bot.tree.dispatch_interaction(interaction)
AttributeError: 'CommandTree' object has no attribute 'dispatch_interaction'
WARNING:discord.client:PyNaCl is not installed, voice will NOT be supported
ERROR:discord.app_commands.tree:Ignoring exception in command 'inventory'
Traceback (most recent call last):
  File "C:\Users\oakne\AppData\Roaming\Python\Python310\site-packages\discord\app_commands\commands.py", line 862, in _do_call
    return await self._callback(interaction, **params)  # type: ignore
  File "C:\Users\oakne\Desktop\DiscordBots\KittyKaravans\Kitties&Karavans.py", line 275, in inventory
    value = user_message_counts[member.name][emoji]
KeyError: 'thrallhouse'

The above exception was the direct cause of the following exception:

Traceback (most recent call last):
  File "C:\Users\oakne\AppData\Roaming\Python\Python310\site-packages\discord\app_commands\tree.py", line 1242, in _call
    await command._invoke_with_namespace(interaction, namespace)
  File "C:\Users\oakne\AppData\Roaming\Python\Python310\site-packages\discord\app_commands\commands.py", line 887, in _invoke_with_namespace
    return await self._do_call(interaction, transformed_values)
  File "C:\Users\oakne\AppData\Roaming\Python\Python310\site-packages\discord\app_commands\commands.py", line 880, in _do_call
    raise CommandInvokeError(self, e) from e
discord.app_commands.errors.CommandInvokeError: Command 'inventory' raised an exception: KeyError: 'thrallhouse'
ERROR:discord.client:Ignoring exception in on_interaction
Traceback (most recent call last):
  File "C:\Users\oakne\AppData\Roaming\Python\Python310\site-packages\discord\client.py", line 409, in _run_event
    await coro(*args, **kwargs)
  File "C:\Users\oakne\Desktop\DiscordBots\KittyKaravans\Kitties&Karavans.py", line 84, in on_interaction
    await bot.tree.dispatch_interaction(interaction)
AttributeError: 'CommandTree' object has no attribute 'dispatch_interaction'
WARNING:discord.client:PyNaCl is not installed, voice will NOT be supported
ERROR:discord.app_commands.tree:Ignoring exception in command 'inventory'
Traceback (most recent call last):
  File "C:\Users\oakne\AppData\Roaming\Python\Python310\site-packages\discord\app_commands\commands.py", line 862, in _do_call
    return await self._callback(interaction, **params)  # type: ignore
  File "C:\Users\oakne\Desktop\DiscordBots\KittyKaravans\Kitties&Karavans.py", line 275, in inventory
    value = user_message_counts[member.name][emoji]
KeyError: 'thrallhouse'

The above exception was the direct cause of the following exception:

Traceback (most recent call last):
  File "C:\Users\oakne\AppData\Roaming\Python\Python310\site-packages\discord\app_commands\tree.py", line 1242, in _call
    await command._invoke_with_namespace(interaction, namespace)
  File "C:\Users\oakne\AppData\Roaming\Python\Python310\site-packages\discord\app_commands\commands.py", line 887, in _invoke_with_namespace
    return await self._do_call(interaction, transformed_values)
  File "C:\Users\oakne\AppData\Roaming\Python\Python310\site-packages\discord\app_commands\commands.py", line 880, in _do_call
    raise CommandInvokeError(self, e) from e
discord.app_commands.errors.CommandInvokeError: Command 'inventory' raised an exception: KeyError: 'thrallhouse'
ERROR:discord.client:Ignoring exception in on_interaction
Traceback (most recent call last):
  File "C:\Users\oakne\AppData\Roaming\Python\Python310\site-packages\discord\client.py", line 409, in _run_event
    await coro(*args, **kwargs)
  File "C:\Users\oakne\Desktop\DiscordBots\KittyKaravans\Kitties&Karavans.py", line 84, in on_interaction
    await bot.tree.dispatch_interaction(interaction)
AttributeError: 'CommandTree' object has no attribute 'dispatch_interaction'
WARNING:discord.client:PyNaCl is not installed, voice will NOT be supported
ERROR:discord.client:Ignoring exception in on_interaction
Traceback (most recent call last):
  File "C:\Users\oakne\AppData\Roaming\Python\Python310\site-packages\discord\client.py", line 409, in _run_event
    await coro(*args, **kwargs)
  File "C:\Users\oakne\Desktop\DiscordBots\KittyKaravans\Kitties&Karavans.py", line 84, in on_interaction
    await bot.tree.dispatch_interaction(interaction)
AttributeError: 'CommandTree' object has no attribute 'dispatch_interaction'
ERROR:discord.client:Ignoring exception in on_interaction
Traceback (most recent call last):
  File "C:\Users\oakne\AppData\Roaming\Python\Python310\site-packages\discord\client.py", line 409, in _run_event
    await coro(*args, **kwargs)
  File "C:\Users\oakne\Desktop\DiscordBots\KittyKaravans\Kitties&Karavans.py", line 84, in on_interaction
    await bot.tree.dispatch_interaction(interaction)
AttributeError: 'CommandTree' object has no attribute 'dispatch_interaction'
ERROR:discord.client:Ignoring exception in on_interaction
Traceback (most recent call last):
  File "C:\Users\oakne\AppData\Roaming\Python\Python310\site-packages\discord\client.py", line 409, in _run_event
    await coro(*args, **kwargs)
  File "C:\Users\oakne\Desktop\DiscordBots\KittyKaravans\Kitties&Karavans.py", line 84, in on_interaction
    await bot.tree.dispatch_interaction(interaction)
AttributeError: 'CommandTree' object has no attribute 'dispatch_interaction'
ERROR:discord.client:Ignoring exception in on_interaction
Traceback (most recent call last):
  File "C:\Users\oakne\AppData\Roaming\Python\Python310\site-packages\discord\client.py", line 409, in _run_event
    await coro(*args, **kwargs)
  File "C:\Users\oakne\Desktop\DiscordBots\KittyKaravans\Kitties&Karavans.py", line 84, in on_interaction
    await bot.tree.dispatch_interaction(interaction)
AttributeError: 'CommandTree' object has no attribute 'dispatch_interaction'
