WARNING:discord.client:PyNaCl is not installed, voice will NOT be supported
WARNING:discord.client:PyNaCl is not installed, voice will NOT be supported
ERROR:discord.client:Ignoring exception in on_interaction
Traceback (most recent call last):
  File "C:\Users\oakne\AppData\Roaming\Python\Python310\site-packages\discord\client.py", line 409, in _run_event
    await coro(*args, **kwargs)
  File "C:\Users\oakne\Desktop\DiscordBots\KittyKaravans\Kitties&Karavans.py", line 82, in on_interaction
    await bot.tree.dispatch_interaction(interaction)
AttributeError: 'CommandTree' object has no attribute 'dispatch_interaction'
ERROR:discord.client:Ignoring exception in on_interaction
Traceback (most recent call last):
  File "C:\Users\oakne\AppData\Roaming\Python\Python310\site-packages\discord\client.py", line 409, in _run_event
    await coro(*args, **kwargs)
  File "C:\Users\oakne\Desktop\DiscordBots\KittyKaravans\Kitties&Karavans.py", line 82, in on_interaction
    await bot.tree.dispatch_interaction(interaction)
AttributeError: 'CommandTree' object has no attribute 'dispatch_interaction'
ERROR:discord.app_commands.tree:Ignoring exception in command 'upgrade'
Traceback (most recent call last):
  File "C:\Users\oakne\AppData\Roaming\Python\Python310\site-packages\discord\app_commands\commands.py", line 862, in _do_call
    return await self._callback(interaction, **params)  # type: ignore
  File "C:\Users\oakne\Desktop\DiscordBots\KittyKaravans\Kitties&Karavans.py", line 355, in inventory
    await interaction.response.send_message("You are not in any karavan.")
  File "C:\Users\oakne\AppData\Roaming\Python\Python310\site-packages\discord\interactions.py", line 743, in send_message
    raise InteractionResponded(self._parent)
discord.errors.InteractionResponded: This interaction has already been responded to before

The above exception was the direct cause of the following exception:

Traceback (most recent call last):
  File "C:\Users\oakne\AppData\Roaming\Python\Python310\site-packages\discord\app_commands\tree.py", line 1242, in _call
    await command._invoke_with_namespace(interaction, namespace)
  File "C:\Users\oakne\AppData\Roaming\Python\Python310\site-packages\discord\app_commands\commands.py", line 887, in _invoke_with_namespace
    return await self._do_call(interaction, transformed_values)
  File "C:\Users\oakne\AppData\Roaming\Python\Python310\site-packages\discord\app_commands\commands.py", line 880, in _do_call
    raise CommandInvokeError(self, e) from e
discord.app_commands.errors.CommandInvokeError: Command 'upgrade' raised an exception: InteractionResponded: This interaction has already been responded to before
WARNING:discord.client:PyNaCl is not installed, voice will NOT be supported
ERROR:discord.client:Ignoring exception in on_interaction
Traceback (most recent call last):
  File "C:\Users\oakne\AppData\Roaming\Python\Python310\site-packages\discord\client.py", line 409, in _run_event
    await coro(*args, **kwargs)
  File "C:\Users\oakne\Desktop\DiscordBots\KittyKaravans\Kitties&Karavans.py", line 82, in on_interaction
    await bot.tree.dispatch_interaction(interaction)
AttributeError: 'CommandTree' object has no attribute 'dispatch_interaction'
ERROR:discord.client:Ignoring exception in on_interaction
Traceback (most recent call last):
  File "C:\Users\oakne\AppData\Roaming\Python\Python310\site-packages\discord\client.py", line 409, in _run_event
    await coro(*args, **kwargs)
  File "C:\Users\oakne\Desktop\DiscordBots\KittyKaravans\Kitties&Karavans.py", line 82, in on_interaction
    await bot.tree.dispatch_interaction(interaction)
AttributeError: 'CommandTree' object has no attribute 'dispatch_interaction'
ERROR:discord.app_commands.tree:Ignoring exception in command 'upgrade'
Traceback (most recent call last):
  File "C:\Users\oakne\AppData\Roaming\Python\Python310\site-packages\discord\app_commands\commands.py", line 862, in _do_call
    return await self._callback(interaction, **params)  # type: ignore
  File "C:\Users\oakne\Desktop\DiscordBots\KittyKaravans\Kitties&Karavans.py", line 356, in inventory
    await interaction.response.send_message("You are not in any karavan.")
  File "C:\Users\oakne\AppData\Roaming\Python\Python310\site-packages\discord\interactions.py", line 743, in send_message
    raise InteractionResponded(self._parent)
discord.errors.InteractionResponded: This interaction has already been responded to before

The above exception was the direct cause of the following exception:

Traceback (most recent call last):
  File "C:\Users\oakne\AppData\Roaming\Python\Python310\site-packages\discord\app_commands\tree.py", line 1242, in _call
    await command._invoke_with_namespace(interaction, namespace)
  File "C:\Users\oakne\AppData\Roaming\Python\Python310\site-packages\discord\app_commands\commands.py", line 887, in _invoke_with_namespace
    return await self._do_call(interaction, transformed_values)
  File "C:\Users\oakne\AppData\Roaming\Python\Python310\site-packages\discord\app_commands\commands.py", line 880, in _do_call
    raise CommandInvokeError(self, e) from e
discord.app_commands.errors.CommandInvokeError: Command 'upgrade' raised an exception: InteractionResponded: This interaction has already been responded to before
WARNING:discord.client:PyNaCl is not installed, voice will NOT be supported
ERROR:discord.client:Ignoring exception in on_interaction
Traceback (most recent call last):
  File "C:\Users\oakne\AppData\Roaming\Python\Python310\site-packages\discord\client.py", line 409, in _run_event
    await coro(*args, **kwargs)
  File "C:\Users\oakne\Desktop\DiscordBots\KittyKaravans\Kitties&Karavans.py", line 82, in on_interaction
    await bot.tree.dispatch_interaction(interaction)
AttributeError: 'CommandTree' object has no attribute 'dispatch_interaction'
ERROR:discord.client:Ignoring exception in on_interaction
Traceback (most recent call last):
  File "C:\Users\oakne\AppData\Roaming\Python\Python310\site-packages\discord\client.py", line 409, in _run_event
    await coro(*args, **kwargs)
  File "C:\Users\oakne\Desktop\DiscordBots\KittyKaravans\Kitties&Karavans.py", line 82, in on_interaction
    await bot.tree.dispatch_interaction(interaction)
AttributeError: 'CommandTree' object has no attribute 'dispatch_interaction'
ERROR:discord.app_commands.tree:Ignoring exception in command 'upgrade'
Traceback (most recent call last):
  File "C:\Users\oakne\AppData\Roaming\Python\Python310\site-packages\discord\app_commands\commands.py", line 862, in _do_call
    return await self._callback(interaction, **params)  # type: ignore
  File "C:\Users\oakne\Desktop\DiscordBots\KittyKaravans\Kitties&Karavans.py", line 357, in inventory
    await interaction.response.send_message("You are not in any karavan.")
  File "C:\Users\oakne\AppData\Roaming\Python\Python310\site-packages\discord\interactions.py", line 743, in send_message
    raise InteractionResponded(self._parent)
discord.errors.InteractionResponded: This interaction has already been responded to before

The above exception was the direct cause of the following exception:

Traceback (most recent call last):
  File "C:\Users\oakne\AppData\Roaming\Python\Python310\site-packages\discord\app_commands\tree.py", line 1242, in _call
    await command._invoke_with_namespace(interaction, namespace)
  File "C:\Users\oakne\AppData\Roaming\Python\Python310\site-packages\discord\app_commands\commands.py", line 887, in _invoke_with_namespace
    return await self._do_call(interaction, transformed_values)
  File "C:\Users\oakne\AppData\Roaming\Python\Python310\site-packages\discord\app_commands\commands.py", line 880, in _do_call
    raise CommandInvokeError(self, e) from e
discord.app_commands.errors.CommandInvokeError: Command 'upgrade' raised an exception: InteractionResponded: This interaction has already been responded to before
WARNING:discord.client:PyNaCl is not installed, voice will NOT be supported
ERROR:discord.client:Ignoring exception in on_interaction
Traceback (most recent call last):
  File "C:\Users\oakne\AppData\Roaming\Python\Python310\site-packages\discord\client.py", line 409, in _run_event
    await coro(*args, **kwargs)
  File "C:\Users\oakne\Desktop\DiscordBots\KittyKaravans\Kitties&Karavans.py", line 82, in on_interaction
    await bot.tree.dispatch_interaction(interaction)
AttributeError: 'CommandTree' object has no attribute 'dispatch_interaction'
ERROR:discord.client:Ignoring exception in on_interaction
Traceback (most recent call last):
  File "C:\Users\oakne\AppData\Roaming\Python\Python310\site-packages\discord\client.py", line 409, in _run_event
    await coro(*args, **kwargs)
  File "C:\Users\oakne\Desktop\DiscordBots\KittyKaravans\Kitties&Karavans.py", line 82, in on_interaction
    await bot.tree.dispatch_interaction(interaction)
AttributeError: 'CommandTree' object has no attribute 'dispatch_interaction'
ERROR:discord.app_commands.tree:Ignoring exception in command 'upgrade'
Traceback (most recent call last):
  File "C:\Users\oakne\AppData\Roaming\Python\Python310\site-packages\discord\app_commands\commands.py", line 862, in _do_call
    return await self._callback(interaction, **params)  # type: ignore
  File "C:\Users\oakne\Desktop\DiscordBots\KittyKaravans\Kitties&Karavans.py", line 355, in inventory
    await interaction.response.send_message("You are not in any karavan.")
  File "C:\Users\oakne\AppData\Roaming\Python\Python310\site-packages\discord\interactions.py", line 743, in send_message
    raise InteractionResponded(self._parent)
discord.errors.InteractionResponded: This interaction has already been responded to before

The above exception was the direct cause of the following exception:

Traceback (most recent call last):
  File "C:\Users\oakne\AppData\Roaming\Python\Python310\site-packages\discord\app_commands\tree.py", line 1242, in _call
    await command._invoke_with_namespace(interaction, namespace)
  File "C:\Users\oakne\AppData\Roaming\Python\Python310\site-packages\discord\app_commands\commands.py", line 887, in _invoke_with_namespace
    return await self._do_call(interaction, transformed_values)
  File "C:\Users\oakne\AppData\Roaming\Python\Python310\site-packages\discord\app_commands\commands.py", line 880, in _do_call
    raise CommandInvokeError(self, e) from e
discord.app_commands.errors.CommandInvokeError: Command 'upgrade' raised an exception: InteractionResponded: This interaction has already been responded to before
WARNING:discord.client:PyNaCl is not installed, voice will NOT be supported
ERROR:discord.client:Ignoring exception in on_interaction
Traceback (most recent call last):
  File "C:\Users\oakne\AppData\Roaming\Python\Python310\site-packages\discord\client.py", line 409, in _run_event
    await coro(*args, **kwargs)
  File "C:\Users\oakne\Desktop\DiscordBots\KittyKaravans\Kitties&Karavans.py", line 82, in on_interaction
    await bot.tree.dispatch_interaction(interaction)
AttributeError: 'CommandTree' object has no attribute 'dispatch_interaction'
ERROR:discord.client:Ignoring exception in on_interaction
Traceback (most recent call last):
  File "C:\Users\oakne\AppData\Roaming\Python\Python310\site-packages\discord\client.py", line 409, in _run_event
    await coro(*args, **kwargs)
  File "C:\Users\oakne\Desktop\DiscordBots\KittyKaravans\Kitties&Karavans.py", line 82, in on_interaction
    await bot.tree.dispatch_interaction(interaction)
AttributeError: 'CommandTree' object has no attribute 'dispatch_interaction'
ERROR:discord.app_commands.tree:Ignoring exception in command 'upgrade'
Traceback (most recent call last):
  File "C:\Users\oakne\AppData\Roaming\Python\Python310\site-packages\discord\app_commands\commands.py", line 862, in _do_call
    return await self._callback(interaction, **params)  # type: ignore
  File "C:\Users\oakne\Desktop\DiscordBots\KittyKaravans\Kitties&Karavans.py", line 355, in inventory
    await interaction.response.send_message("You are not in any karavan.")
  File "C:\Users\oakne\AppData\Roaming\Python\Python310\site-packages\discord\interactions.py", line 743, in send_message
    raise InteractionResponded(self._parent)
discord.errors.InteractionResponded: This interaction has already been responded to before

The above exception was the direct cause of the following exception:

Traceback (most recent call last):
  File "C:\Users\oakne\AppData\Roaming\Python\Python310\site-packages\discord\app_commands\tree.py", line 1242, in _call
    await command._invoke_with_namespace(interaction, namespace)
  File "C:\Users\oakne\AppData\Roaming\Python\Python310\site-packages\discord\app_commands\commands.py", line 887, in _invoke_with_namespace
    return await self._do_call(interaction, transformed_values)
  File "C:\Users\oakne\AppData\Roaming\Python\Python310\site-packages\discord\app_commands\commands.py", line 880, in _do_call
    raise CommandInvokeError(self, e) from e
discord.app_commands.errors.CommandInvokeError: Command 'upgrade' raised an exception: InteractionResponded: This interaction has already been responded to before
WARNING:discord.client:PyNaCl is not installed, voice will NOT be supported
ERROR:discord.client:Ignoring exception in on_interaction
Traceback (most recent call last):
  File "C:\Users\oakne\AppData\Roaming\Python\Python310\site-packages\discord\client.py", line 409, in _run_event
    await coro(*args, **kwargs)
  File "C:\Users\oakne\Desktop\DiscordBots\KittyKaravans\Kitties&Karavans.py", line 82, in on_interaction
    await bot.tree.dispatch_interaction(interaction)
AttributeError: 'CommandTree' object has no attribute 'dispatch_interaction'
ERROR:discord.app_commands.tree:Ignoring exception in command 'upgrade'
Traceback (most recent call last):
  File "C:\Users\oakne\AppData\Roaming\Python\Python310\site-packages\discord\app_commands\commands.py", line 862, in _do_call
    return await self._callback(interaction, **params)  # type: ignore
  File "C:\Users\oakne\Desktop\DiscordBots\KittyKaravans\Kitties&Karavans.py", line 342, in inventory
    button = reactionmenu.create_button(style=reactionmenu.Style.PRIMARY, label=emoji, custom_id=emoji)
AttributeError: module 'reactionmenu' has no attribute 'create_button'

The above exception was the direct cause of the following exception:

Traceback (most recent call last):
  File "C:\Users\oakne\AppData\Roaming\Python\Python310\site-packages\discord\app_commands\tree.py", line 1242, in _call
    await command._invoke_with_namespace(interaction, namespace)
  File "C:\Users\oakne\AppData\Roaming\Python\Python310\site-packages\discord\app_commands\commands.py", line 887, in _invoke_with_namespace
    return await self._do_call(interaction, transformed_values)
  File "C:\Users\oakne\AppData\Roaming\Python\Python310\site-packages\discord\app_commands\commands.py", line 880, in _do_call
    raise CommandInvokeError(self, e) from e
discord.app_commands.errors.CommandInvokeError: Command 'upgrade' raised an exception: AttributeError: module 'reactionmenu' has no attribute 'create_button'
ERROR:discord.client:Ignoring exception in on_interaction
Traceback (most recent call last):
  File "C:\Users\oakne\AppData\Roaming\Python\Python310\site-packages\discord\client.py", line 409, in _run_event
    await coro(*args, **kwargs)
  File "C:\Users\oakne\Desktop\DiscordBots\KittyKaravans\Kitties&Karavans.py", line 82, in on_interaction
    await bot.tree.dispatch_interaction(interaction)
AttributeError: 'CommandTree' object has no attribute 'dispatch_interaction'
WARNING:discord.client:PyNaCl is not installed, voice will NOT be supported
ERROR:discord.client:Ignoring exception in on_interaction
Traceback (most recent call last):
  File "C:\Users\oakne\AppData\Roaming\Python\Python310\site-packages\discord\client.py", line 409, in _run_event
    await coro(*args, **kwargs)
  File "C:\Users\oakne\Desktop\DiscordBots\KittyKaravans\Kitties&Karavans.py", line 82, in on_interaction
    await bot.tree.dispatch_interaction(interaction)
AttributeError: 'CommandTree' object has no attribute 'dispatch_interaction'
ERROR:discord.client:Ignoring exception in on_interaction
Traceback (most recent call last):
  File "C:\Users\oakne\AppData\Roaming\Python\Python310\site-packages\discord\client.py", line 409, in _run_event
    await coro(*args, **kwargs)
  File "C:\Users\oakne\Desktop\DiscordBots\KittyKaravans\Kitties&Karavans.py", line 82, in on_interaction
    await bot.tree.dispatch_interaction(interaction)
AttributeError: 'CommandTree' object has no attribute 'dispatch_interaction'
WARNING:discord.client:PyNaCl is not installed, voice will NOT be supported
ERROR:discord.client:Ignoring exception in on_interaction
Traceback (most recent call last):
  File "C:\Users\oakne\AppData\Roaming\Python\Python310\site-packages\discord\client.py", line 409, in _run_event
    await coro(*args, **kwargs)
  File "C:\Users\oakne\Desktop\DiscordBots\KittyKaravans\Kitties&Karavans.py", line 82, in on_interaction
    await bot.tree.dispatch_interaction(interaction)
AttributeError: 'CommandTree' object has no attribute 'dispatch_interaction'
ERROR:discord.client:Ignoring exception in on_interaction
Traceback (most recent call last):
  File "C:\Users\oakne\AppData\Roaming\Python\Python310\site-packages\discord\client.py", line 409, in _run_event
    await coro(*args, **kwargs)
  File "C:\Users\oakne\Desktop\DiscordBots\KittyKaravans\Kitties&Karavans.py", line 82, in on_interaction
    await bot.tree.dispatch_interaction(interaction)
AttributeError: 'CommandTree' object has no attribute 'dispatch_interaction'
ERROR:discord.client:Attempting a reconnect in 0.69s
Traceback (most recent call last):
  File "C:\Users\oakne\AppData\Roaming\Python\Python310\site-packages\aiohttp\connector.py", line 1154, in _create_direct_connection
    hosts = await asyncio.shield(host_resolved)
  File "C:\Users\oakne\AppData\Roaming\Python\Python310\site-packages\aiohttp\connector.py", line 880, in _resolve_host
    addrs = await self._resolver.resolve(host, port, family=self._family)
  File "C:\Users\oakne\AppData\Roaming\Python\Python310\site-packages\aiohttp\resolver.py", line 33, in resolve
    infos = await self._loop.getaddrinfo(
  File "C:\Users\oakne\AppData\Local\Programs\Python\Python310\lib\asyncio\base_events.py", line 860, in getaddrinfo
    return await self.run_in_executor(
  File "C:\Users\oakne\AppData\Local\Programs\Python\Python310\lib\concurrent\futures\thread.py", line 58, in run
    result = self.fn(*self.args, **self.kwargs)
  File "C:\Users\oakne\AppData\Local\Programs\Python\Python310\lib\socket.py", line 955, in getaddrinfo
    for res in _socket.getaddrinfo(host, port, family, type, proto, flags):
socket.gaierror: [Errno 11001] getaddrinfo failed

The above exception was the direct cause of the following exception:

Traceback (most recent call last):
  File "C:\Users\oakne\AppData\Roaming\Python\Python310\site-packages\discord\client.py", line 624, in connect
    self.ws = await asyncio.wait_for(coro, timeout=60.0)
  File "C:\Users\oakne\AppData\Local\Programs\Python\Python310\lib\asyncio\tasks.py", line 445, in wait_for
    return fut.result()
  File "C:\Users\oakne\AppData\Roaming\Python\Python310\site-packages\discord\gateway.py", line 372, in from_client
    socket = await client.http.ws_connect(str(url))
  File "C:\Users\oakne\AppData\Roaming\Python\Python310\site-packages\discord\http.py", line 536, in ws_connect
    return await self.__session.ws_connect(url, **kwargs)
  File "C:\Users\oakne\AppData\Roaming\Python\Python310\site-packages\aiohttp\client.py", line 776, in _ws_connect
    resp = await self.request(
  File "C:\Users\oakne\AppData\Roaming\Python\Python310\site-packages\aiohttp\client.py", line 535, in _request
    conn = await self._connector.connect(
  File "C:\Users\oakne\AppData\Roaming\Python\Python310\site-packages\aiohttp\connector.py", line 542, in connect
    proto = await self._create_connection(req, traces, timeout)
  File "C:\Users\oakne\AppData\Roaming\Python\Python310\site-packages\aiohttp\connector.py", line 907, in _create_connection
    _, proto = await self._create_direct_connection(req, traces, timeout)
  File "C:\Users\oakne\AppData\Roaming\Python\Python310\site-packages\aiohttp\connector.py", line 1166, in _create_direct_connection
    raise ClientConnectorError(req.connection_key, exc) from exc
aiohttp.client_exceptions.ClientConnectorError: Cannot connect to host gateway-us-east1-c.discord.gg:443 ssl:default [getaddrinfo failed]
